Workbook

Sheet Intro
B4: All data in IGZs, and 2011 DZs
B6: Scotland is average of LAs
B8: Imputed data has been removed in this version
B10: Some indicators are flipped as the model assumes that high is good, and for a number of indicators that isn't the case
B11: Crime
B12: Child Poverty
B13: Emergency Admissions
B14: Early Mortality
B16: Help sheet that explains methodology here: | G16: https://impservihub.sharepoint.com/:w:/r/sites/tpi-benchmarking/Shared%20Documents/CPP%20Benchmarking/DATA%20LIBRARY/2018%20Data%20Library/Inequality%20tool%20data/Duncan_Index_Feb_19/DI%20help%20sheet_feb_19.docx?d=w34893cdbb8f241e6b72080985edc35d4&csf=1&e=CUd1Hn
B20: At Scotland level looks like for positive destinations inequality is reducing, whereas for Emgerency admissions it is increasing. It is worth remembering that we have added imputed data here, and for positive destinations there are 4 or 5 years of imputed data at the end.

Sheet Duncan index by FINALOct24
B1: year | C1: la | D1: total.pop | E1: crime | F1: CP | G1: Attain | H1: PD | I1: EA | J1: Depop | K1: EM
A2: 1 | B2: 2010 | C2: Aberdeen City | D2: 236643.52 | E2: -0.31064156 | F2: -0.35355574 | G2: 0.35539978 | H2: 0.24255258 | I2: -0.288222 | J2: 0.048720108 | K2: -0.29766635
A3: 2 | B3: 2010 | C3: Aberdeenshire | D3: 301718.63 | E3: -0.24549897 | F3: -0.30953681 | G3: 0.25735594 | H3: 0.13957667 | I3: -0.18625955 | J3: -0.15377746 | K3: -0.28375368
A4: 3 | B4: 2010 | C4: Angus | D4: 126420.33 | E4: -0.30114737 | F4: -0.27815757 | G4: 0.28537313 | H4: 0.16471239 | I4: -0.10855666 | J4: -0.097570569 | K4: -0.28251099
A5: 4 | B5: 2010 | C5: Argyll and Bute | D5: 92844.874 | E5: -0.18157782 | F5: -0.10902692 | G5: 0.20396839 | H5: 0.071757054 | I5: -0.14280568 | J5: -0.001866626 | K5: -0.22063004
A6: 5 | B6: 2010 | C6: Clackmannanshire | D6: 63020.336 | E6: -0.18340147 | F6: -0.17300484 | G6: 0.1571465 | H6: 0.23117701 | I6: -0.12316926 | J6: -0.098400087 | K6: -0.1765589
A7: 6 | B7: 2010 | C7: Dumfries and Galloway | D7: 158069.13 | E7: -0.17998727 | F7: -0.14487224 | G7: 0.16471111 | H7: 0.14254854 | I7: -0.12594931 | J7: -0.030775378 | K7: -0.16836663
A8: 7 | B8: 2010 | C8: Dundee City | D8: 161884.75 | E8: -0.26256778 | F8: -0.25097038 | G8: 0.29290429 | H8: 0.24718332 | I8: -0.27689981 | J8: -0.042050214 | K8: -0.26297826
A9: 8 | B9: 2010 | C9: East Ayrshire | D9: 134188.46 | E9: -0.19847909 | F9: -0.25568934 | G9: 0.2443133 | H9: 0.21884757 | I9: -0.21883799 | J9: -0.068549689 | K9: -0.25876824
A10: 9 | B10: 2010 | C10: East Dunbartonshire | D10: 108352.27 | E10: -0.066133154 | F10: -0.32769533 | G10: 0.32974475 | H10: 0.25716776 | I10: -0.30492147 | J10: 0.029964814 | K10: -0.34809027
A11: 10 | B11: 2010 | C11: East Lothian | D11: 117273.82 | E11: -0.1951723 | F11: -0.178836 | G11: 0.19920204 | H11: 0.18981659 | I11: -0.17043262 | J11: -0.0017950171 | K11: -0.15873801
A12: 11 | B12: 2010 | C12: East Renfrewshire | D12: 92208.069 | E12: -0.34522213 | F12: -0.38154307 | G12: 0.40345989 | H12: 0.32955804 | I12: -0.23142111 | J12: -0.00026154031 | K12: -0.37802353
A13: 12 | B13: 2010 | C13: Edinburgh, City of | D13: 559377.68 | E13: -0.33361369 | F13: -0.37287495 | G13: 0.40402271 | H13: 0.31577612 | I13: -0.36650288 | J13: 0.1020651 | K13: -0.38758363
... A417: 416 | B417: 2022 | C417: West Lothian | D417: 181310 | E417: -0.232325 | F417: -0.2896955 | G417: 0.27682111 | H417: 0.18238456 | I417: -0.22665549 | J417: 0.0062971618 | K417: -0.27575184

Sheet Flipped data - to use
B1: year | C1: la | D1: total.pop | E1: crime | F1: CP | G1: Attain | H1: PD | I1: EA | J1: Depop | K1: EM
A2: 1 | B2: 2010 | C2: Aberdeen City | D2: 226984.75 | E2: ='Duncan index by FINALOct24'!E2*-1 -> 0.31064156 | I2: ='Duncan index by FINALOct24'!I2*-1 -> 0.288222 | J2: ='Duncan index by FINALOct24'!J2 -> 0.048720108 | K2: ='Duncan index by FINALOct24'!K2*-1 -> 0.29766635
A3: 2 | B3: 2010 | C3: Aberdeenshire | D3: 286973.38 | E3: ='Duncan index by FINALOct24'!E3*-1 -> 0.24549897 | I3: ='Duncan index by FINALOct24'!I3*-1 -> 0.18625955 | J3: ='Duncan index by FINALOct24'!J3 -> -0.15377746 | K3: ='Duncan index by FINALOct24'!K3*-1 -> 0.28375368
A4: 3 | B4: 2010 | C4: Angus | D4: 124726.42 | E4: ='Duncan index by FINALOct24'!E4*-1 -> 0.30114737 | I4: ='Duncan index by FINALOct24'!I4*-1 -> 0.10855666 | J4: ='Duncan index by FINALOct24'!J4 -> -0.097570569 | K4: ='Duncan index by FINALOct24'!K4*-1 -> 0.28251099
A5: 4 | B5: 2010 | C5: Argyll and Bute | D5: 95155.922 | E5: ='Duncan index by FINALOct24'!E5*-1 -> 0.18157782 | I5: ='Duncan index by FINALOct24'!I5*-1 -> 0.14280568 | J5: ='Duncan index by FINALOct24'!J5 -> -0.001866626 | K5: ='Duncan index by FINALOct24'!K5*-1 -> 0.22063004
A6: 5 | B6: 2010 | C6: Clackmannanshire | D6: 61215.619 | E6: ='Duncan index by FINALOct24'!E6*-1 -> 0.18340147 | I6: ='Duncan index by FINALOct24'!I6*-1 -> 0.12316926 | J6: ='Duncan index by FINALOct24'!J6 -> -0.098400087 | K6: ='Duncan index by FINALOct24'!K6*-1 -> 0.1765589
A7: 6 | B7: 2010 | C7: Dumfries and Galloway | D7: 157522.88 | E7: ='Duncan index by FINALOct24'!E7*-1 -> 0.17998727 | I7: ='Duncan index by FINALOct24'!I7*-1 -> 0.12594931 | J7: ='Duncan index by FINALOct24'!J7 -> -0.030775378 | K7: ='Duncan index by FINALOct24'!K7*-1 -> 0.16836663
A8: 7 | B8: 2010 | C8: Dundee City | D8: 155431.2 | E8: ='Duncan index by FINALOct24'!E8*-1 -> 0.26256778 | I8: ='Duncan index by FINALOct24'!I8*-1 -> 0.27689981 | J8: ='Duncan index by FINALOct24'!J8 -> -0.042050214 | K8: ='Duncan index by FINALOct24'!K8*-1 -> 0.26297826
A9: 8 | B9: 2010 | C9: East Ayrshire | D9: 130870.36 | E9: ='Duncan index by FINALOct24'!E9*-1 -> 0.19847909 | I9: ='Duncan index by FINALOct24'!I9*-1 -> 0.21883799 | J9: ='Duncan index by FINALOct24'!J9 -> -0.068549689 | K9: ='Duncan index by FINALOct24'!K9*-1 -> 0.25876824
A10: 9 | B10: 2010 | C10: East Dunbartonshire | D10: 108266.64 | E10: ='Duncan index by FINALOct24'!E10*-1 -> 0.066133154 | I10: ='Duncan index by FINALOct24'!I10*-1 -> 0.30492147 | J10: ='Duncan index by FINALOct24'!J10 -> 0.029964814 | K10: ='Duncan index by FINALOct24'!K10*-1 -> 0.34809027
A11: 10 | B11: 2010 | C11: East Lothian | D11: 109823.74 | E11: ='Duncan index by FINALOct24'!E11*-1 -> 0.1951723 | I11: ='Duncan index by FINALOct24'!I11*-1 -> 0.17043262 | J11: ='Duncan index by FINALOct24'!J11 -> -0.0017950171 | K11: ='Duncan index by FINALOct24'!K11*-1 -> 0.15873801
A12: 11 | B12: 2010 | C12: East Renfrewshire | D12: 91699.634 | E12: ='Duncan index by FINALOct24'!E12*-1 -> 0.34522213 | I12: ='Duncan index by FINALOct24'!I12*-1 -> 0.23142111 | J12: ='Duncan index by FINALOct24'!J12 -> -0.00026154031 | K12: ='Duncan index by FINALOct24'!K12*-1 -> 0.37802353
A13: 12 | B13: 2010 | C13: Edinburgh, City of | D13: 527536.35 | E13: ='Duncan index by FINALOct24'!E13*-1 -> 0.33361369 | I13: ='Duncan index by FINALOct24'!I13*-1 -> 0.36650288 | J13: ='Duncan index by FINALOct24'!J13 -> 0.1020651 | K13: ='Duncan index by FINALOct24'!K13*-1 -> 0.38758363
... A97: 96 | B97: 2012 | C97: West Lothian | D97: 218381.89 | E97: ='Duncan index by FINALOct24'!E97*-1 -> 0.19168559 | I97: ='Duncan index by FINALOct24'!I97*-1 -> 0.14606981 | J97: ='Duncan index by FINALOct24'!J97 -> 0.066160765 | K97: ='Duncan index by FINALOct24'!K97*-1 -> 0.20605908
A98: 97 | B98: 2013 | C98: Aberdeen City | D98: 236643.4 | E98: ='Duncan index by FINALOct24'!E98*-1 -> 0.26332753 | G98: ='Duncan index by FINALOct24'!G98 -> 0.3534847 | I98: ='Duncan index by FINALOct24'!I98*-1 -> 0.33436911 | J98: ='Duncan index by FINALOct24'!J98 -> 0.0075414866 | K98: ='Duncan index by FINALOct24'!K98*-1 -> 0.28273703
A99: 98 | B99: 2013 | C99: Aberdeenshire | D99: 301718.8 | E99: ='Duncan index by FINALOct24'!E99*-1 -> 0.24094812 | G99: ='Duncan index by FINALOct24'!G99 -> 0.2840029 | I99: ='Duncan index by FINALOct24'!I99*-1 -> 0.20207808 | J99: ='Duncan index by FINALOct24'!J99 -> -0.17304072 | K99: ='Duncan index by FINALOct24'!K99*-1 -> 0.28375163
A100: 99 | B100: 2013 | C100: Angus | D100: 126420.4 | E100: ='Duncan index by FINALOct24'!E100*-1 -> 0.25963043 | G100: ='Duncan index by FINALOct24'!G100 -> 0.28245497 | I100: ='Duncan index by FINALOct24'!I100*-1 -> 0.15984978 | J100: ='Duncan index by FINALOct24'!J100 -> 0.010107884 | K100: ='Duncan index by FINALOct24'!K100*-1 -> 0.27221243
A101: 100 | B101: 2013 | C101: Argyll and Bute | D101: 92844.8 | E101: ='Duncan index by FINALOct24'!E101*-1 -> 0.17620388 | G101: ='Duncan index by FINALOct24'!G101 -> 0.17618174 | I101: ='Duncan index by FINALOct24'!I101*-1 -> 0.19133395 | J101: ='Duncan index by FINALOct24'!J101 -> -0.091358155 | K101: ='Duncan index by FINALOct24'!K101*-1 -> 0.19508588
A102: 101 | B102: 2013 | C102: Clackmannanshire | D102: 63020.3 | E102: ='Duncan index by FINALOct24'!E102*-1 -> 0.20076096 | G102: ='Duncan index by FINALOct24'!G102 -> 0.23311495 | I102: ='Duncan index by FINALOct24'!I102*-1 -> 0.13608257 | J102: ='Duncan index by FINALOct24'!J102 -> -0.059801176 | K102: ='Duncan index by FINALOct24'!K102*-1 -> 0.22489928
A103: 102 | B103: 2013 | C103: Dumfries and Galloway | D103: 158069.1 | E103: ='Duncan index by FINALOct24'!E103*-1 -> 0.19439329 | G103: ='Duncan index by FINALOct24'!G103 -> 0.20056016 | I103: ='Duncan index by FINALOct24'!I103*-1 -> 0.15167066 | J103: ='Duncan index by FINALOct24'!J103 -> -0.0041000474 | K103: ='Duncan index by FINALOct24'!K103*-1 -> 0.1994405
A104: 103 | B104: 2013 | C104: Dundee City | D104: 161884.6 | E104: ='Duncan index by FINALOct24'!E104*-1 -> 0.2796959 | G104: ='Duncan index by FINALOct24'!G104 -> 0.3269266 | I104: ='Duncan index by FINALOct24'!I104*-1 -> 0.1926335 | J104: ='Duncan index by FINALOct24'!J104 -> -0.10964243 | K104: ='Duncan index by FINALOct24'!K104*-1 -> 0.23261577
A105: 104 | B105: 2013 | C105: East Ayrshire | D105: 134188.6 | E105: ='Duncan index by FINALOct24'!E105*-1 -> 0.06066012 | G105: ='Duncan index by FINALOct24'!G105 -> 0.25696239 | I105: ='Duncan index by FINALOct24'!I105*-1 -> 0.23026058 | J105: ='Duncan index by FINALOct24'!J105 -> -0.046886481 | K105: ='Duncan index by FINALOct24'!K105*-1 -> 0.24507593
A106: 105 | B106: 2013 | C106: East Dunbartonshire | D106: 108352.2 | E106: ='Duncan index by FINALOct24'!E106*-1 -> 0.03963528 | G106: ='Duncan index by FINALOct24'!G106 -> 0.33439568 | I106: ='Duncan index by FINALOct24'!I106*-1 -> 0.33409605 | J106: ='Duncan index by FINALOct24'!J106 -> 0.048749503 | K106: ='Duncan index by FINALOct24'!K106*-1 -> 0.35137562
A107: 106 | B107: 2013 | C107: East Lothian | D107: 117273.7 | E107: ='Duncan index by FINALOct24'!E107*-1 -> 0.18115427 | G107: ='Duncan index by FINALOct24'!G107 -> 0.23135926 | I107: ='Duncan index by FINALOct24'!I107*-1 -> 0.19587723 | J107: ='Duncan index by FINALOct24'!J107 -> 0.090630176 | K107: ='Duncan index by FINALOct24'!K107*-1 -> 0.21300806
A108: 107 | B108: 2013 | C108: East Renfrewshire | D108: 92208.2 | E108: ='Duncan index by FINALOct24'!E108*-1 -> 0.19247419 | G108: ='Duncan index by FINALOct24'!G108 -> 0.39835885 | I108: ='Duncan index by FINALOct24'!I108*-1 -> 0.34548108 | J108: ='Duncan index by FINALOct24'!J108 -> 0.079412143 | K108: ='Duncan index by FINALOct24'!K108*-1 -> 0.38510967
A109: 108 | B109: 2013 | C109: Edinburgh, City of | D109: 559378 | E109: ='Duncan index by FINALOct24'!E109*-1 -> 0.35094061 | G109: ='Duncan index by FINALOct24'!G109 -> 0.44670474 | I109: ='Duncan index by FINALOct24'!I109*-1 -> 0.38474482 | J109: ='Duncan index by FINALOct24'!J109 -> -0.0010532951 | K109: ='Duncan index by FINALOct24'!K109*-1 -> 0.42060911
... A129: 128 | B129: 2013 | C129: West Lothian | D129: 218381.7 | E129: ='Duncan index by FINALOct24'!E129*-1 -> 0.20858694 | G129: ='Duncan index by FINALOct24'!G129 -> 0.25819063 | I129: ='Duncan index by FINALOct24'!I129*-1 -> 0.17767502 | J129: ='Duncan index by FINALOct24'!J129 -> 0.083302962 | K129: ='Duncan index by FINALOct24'!K129*-1 -> 0.22085662
A130: 129 | B130: 2014 | C130: Aberdeen City | D130: 236643.4 | E130: ='Duncan index by FINALOct24'!E130*-1 -> 0.24934958 | F130: ='Duncan index by FINALOct24'!F130*-1 -> 0.35750369 | G130: ='Duncan index by FINALOct24'!G130 -> 0.32822436 | I130: ='Duncan index by FINALOct24'!I130*-1 -> 0.31677917 | J130: ='Duncan index by FINALOct24'!J130 -> -0.018829033 | K130: ='Duncan index by FINALOct24'!K130*-1 -> 0.25270882
A131: 130 | B131: 2014 | C131: Aberdeenshire | D131: 301718.8 | E131: ='Duncan index by FINALOct24'!E131*-1 -> 0.23275962 | F131: ='Duncan index by FINALOct24'!F131*-1 -> 0.32884778 | G131: ='Duncan index by FINALOct24'!G131 -> 0.28689901 | I131: ='Duncan index by FINALOct24'!I131*-1 -> 0.19068897 | J131: ='Duncan index by FINALOct24'!J131 -> -0.17734436 | K131: ='Duncan index by FINALOct24'!K131*-1 -> 0.20046255
A132: 131 | B132: 2014 | C132: Angus | D132: 126420.4 | E132: ='Duncan index by FINALOct24'!E132*-1 -> 0.25015697 | F132: ='Duncan index by FINALOct24'!F132*-1 -> 0.26647897 | G132: ='Duncan index by FINALOct24'!G132 -> 0.27123768 | I132: ='Duncan index by FINALOct24'!I132*-1 -> 0.20806787 | J132: ='Duncan index by FINALOct24'!J132 -> 0.01028743 | K132: ='Duncan index by FINALOct24'!K132*-1 -> 0.2243834
A133: 132 | B133: 2014 | C133: Argyll and Bute | D133: 92844.8 | E133: ='Duncan index by FINALOct24'!E133*-1 -> 0.17018137 | F133: ='Duncan index by FINALOct24'!F133*-1 -> 0.15924345 | G133: ='Duncan index by FINALOct24'!G133 -> 0.19671069 | I133: ='Duncan index by FINALOct24'!I133*-1 -> 0.20060494 | J133: ='Duncan index by FINALOct24'!J133 -> -0.12186526 | K133: ='Duncan index by FINALOct24'!K133*-1 -> 0.17565657
A134: 133 | B134: 2014 | C134: Clackmannanshire | D134: 63020.3 | E134: ='Duncan index by FINALOct24'!E134*-1 -> 0.19762504 | F134: ='Duncan index by FINALOct24'!F134*-1 -> 0.22639616 | G134: ='Duncan index by FINALOct24'!G134 -> 0.2397749 | I134: ='Duncan index by FINALOct24'!I134*-1 -> 0.16264346 | J134: ='Duncan index by FINALOct24'!J134 -> -0.055013546 | K134: ='Duncan index by FINALOct24'!K134*-1 -> 0.18659783
A135: 134 | B135: 2014 | C135: Dumfries and Galloway | D135: 158069.1 | E135: ='Duncan index by FINALOct24'!E135*-1 -> 0.17797318 | F135: ='Duncan index by FINALOct24'!F135*-1 -> 0.2040867 | G135: ='Duncan index by FINALOct24'!G135 -> 0.20290355 | I135: ='Duncan index by FINALOct24'!I135*-1 -> 0.17885351 | J135: ='Duncan index by FINALOct24'!J135 -> -0.022656234 | K135: ='Duncan index by FINALOct24'!K135*-1 -> 0.13951809
A136: 135 | B136: 2014 | C136: Dundee City | D136: 161884.6 | E136: ='Duncan index by FINALOct24'!E136*-1 -> 0.28602755 | F136: ='Duncan index by FINALOct24'!F136*-1 -> 0.28719344 | G136: ='Duncan index by FINALOct24'!G136 -> 0.3242801 | I136: ='Duncan index by FINALOct24'!I136*-1 -> 0.21268379 | J136: ='Duncan index by FINALOct24'!J136 -> -0.10456201 | K136: ='Duncan index by FINALOct24'!K136*-1 -> 0.25201564
A137: 136 | B137: 2014 | C137: East Ayrshire | D137: 134188.6 | E137: ='Duncan index by FINALOct24'!E137*-1 -> 0.12444992 | F137: ='Duncan index by FINALOct24'!F137*-1 -> 0.26862521 | G137: ='Duncan index by FINALOct24'!G137 -> 0.24945557 | I137: ='Duncan index by FINALOct24'!I137*-1 -> 0.22062428 | J137: ='Duncan index by FINALOct24'!J137 -> -0.065805164 | K137: ='Duncan index by FINALOct24'!K137*-1 -> 0.18258336
A138: 137 | B138: 2014 | C138: East Dunbartonshire | D138: 108352.2 | E138: ='Duncan index by FINALOct24'!E138*-1 -> 0.089800937 | F138: ='Duncan index by FINALOct24'!F138*-1 -> 0.32807714 | G138: ='Duncan index by FINALOct24'!G138 -> 0.32459175 | I138: ='Duncan index by FINALOct24'!I138*-1 -> 0.31729074 | J138: ='Duncan index by FINALOct24'!J138 -> 0.050658131 | K138: ='Duncan index by FINALOct24'!K138*-1 -> 0.25392849
A139: 138 | B139: 2014 | C139: East Lothian | D139: 117273.7 | E139: ='Duncan index by FINALOct24'!E139*-1 -> 0.18352709 | F139: ='Duncan index by FINALOct24'!F139*-1 -> 0.22787462 | G139: ='Duncan index by FINALOct24'!G139 -> 0.24179132 | I139: ='Duncan index by FINALOct24'!I139*-1 -> 0.21605177 | J139: ='Duncan index by FINALOct24'!J139 -> 0.071592703 | K139: ='Duncan index by FINALOct24'!K139*-1 -> 0.16682275
A140: 139 | B140: 2014 | C140: East Renfrewshire | D140: 92208.2 | E140: ='Duncan index by FINALOct24'!E140*-1 -> 0.21585913 | F140: ='Duncan index by FINALOct24'!F140*-1 -> 0.39121322 | G140: ='Duncan index by FINALOct24'!G140 -> 0.41079268 | I140: ='Duncan index by FINALOct24'!I140*-1 -> 0.36708324 | J140: ='Duncan index by FINALOct24'!J140 -> 0.070403282 | K140: ='Duncan index by FINALOct24'!K140*-1 -> 0.35685298
A141: 140 | B141: 2014 | C141: Edinburgh, City of | D141: 559378 | E141: ='Duncan index by FINALOct24'!E141*-1 -> 0.33842401 | F141: ='Duncan index by FINALOct24'!F141*-1 -> 0.4165102 | G141: ='Duncan index by FINALOct24'!G141 -> 0.44874447 | I141: ='Duncan index by FINALOct24'!I141*-1 -> 0.40138285 | J141: ='Duncan index by FINALOct24'!J141 -> 0.0077161535 | K141: ='Duncan index by FINALOct24'!K141*-1 -> 0.40317356
... A193: 192 | B193: 2015 | C193: West Lothian | D193: 177150 | E193: ='Duncan index by FINALOct24'!E193*-1 -> 0.20962886 | F193: ='Duncan index by FINALOct24'!F193*-1 -> 0.25467051 | G193: ='Duncan index by FINALOct24'!G193 -> 0.24174822 | I193: ='Duncan index by FINALOct24'!I193*-1 -> 0.20852515 | J193: ='Duncan index by FINALOct24'!J193 -> 0.0508667 | K193: ='Duncan index by FINALOct24'!K193*-1 -> 0.20017354
...

Sheet Scotland Data - use
B1: crime | C1: CP | D1: Attain | E1: PD | F1: EA | G1: Depop | H1: EM
A2: 2010 | B2: =AVERAGEIF('Flipped data - to use'!$B$2:$B$417,'Scotland Data - use'!$A2,'Flipped data - to use'!E$2:E$385) -> 0.20402696 | F2: =AVERAGEIF('Flipped data - to use'!$B$2:$B$417,'Scotland Data - use'!$A2,'Flipped data - to use'!I$2:I$385) -> 0.18261385 | G2: =AVERAGEIF('Flipped data - to use'!$B$2:$B$417,'Scotland Data - use'!$A2,'Flipped data - to use'!J$2:J$385) -> -0.060226749 | H2: =AVERAGEIF('Flipped data - to use'!$B$2:$B$417,'Scotland Data - use'!$A2,'Flipped data - to use'!K$2:K$385) -> 0.23691914
A3: 2011 | B3: =AVERAGEIF('Flipped data - to use'!$B$2:$B$417,'Scotland Data - use'!$A3,'Flipped data - to use'!E$2:E$385) -> 0.1989217 | F3: =AVERAGEIF('Flipped data - to use'!$B$2:$B$417,'Scotland Data - use'!$A3,'Flipped data - to use'!I$2:I$385) -> 0.17961283 | G3: =AVERAGEIF('Flipped data - to use'!$B$2:$B$417,'Scotland Data - use'!$A3,'Flipped data - to use'!J$2:J$385) -> -0.016199621 | H3: =AVERAGEIF('Flipped data - to use'!$B$2:$B$417,'Scotland Data - use'!$A3,'Flipped data - to use'!K$2:K$385) -> 0.23697505
A4: 2012 | B4: =AVERAGEIF('Flipped data - to use'!$B$2:$B$417,'Scotland Data - use'!$A4,'Flipped data - to use'!E$2:E$385) -> 0.18864381 | F4: =AVERAGEIF('Flipped data - to use'!$B$2:$B$417,'Scotland Data - use'!$A4,'Flipped data - to use'!I$2:I$385) -> 0.19169946 | G4: =AVERAGEIF('Flipped data - to use'!$B$2:$B$417,'Scotland Data - use'!$A4,'Flipped data - to use'!J$2:J$385) -> -0.029468231 | H4: =AVERAGEIF('Flipped data - to use'!$B$2:$B$417,'Scotland Data - use'!$A4,'Flipped data - to use'!K$2:K$385) -> 0.23901115
A5: 2013 | B5: =AVERAGEIF('Flipped data - to use'!$B$2:$B$417,'Scotland Data - use'!$A5,'Flipped data - to use'!E$2:E$385) -> 0.18165657 | D5: =AVERAGEIF('Flipped data - to use'!$B$2:$B$417,'Scotland Data - use'!$A5,'Flipped data - to use'!G$2:G$385) -> 0.25685522 | F5: =AVERAGEIF('Flipped data - to use'!$B$2:$B$417,'Scotland Data - use'!$A5,'Flipped data - to use'!I$2:I$385) -> 0.20897692 | G5: =AVERAGEIF('Flipped data - to use'!$B$2:$B$417,'Scotland Data - use'!$A5,'Flipped data - to use'!J$2:J$385) -> -0.04334525 | H5: =AVERAGEIF('Flipped data - to use'!$B$2:$B$417,'Scotland Data - use'!$A5,'Flipped data - to use'!K$2:K$385) -> 0.24551927
A6: 2014 | B6: =AVERAGEIF('Flipped data - to use'!$B$2:$B$417,'Scotland Data - use'!$A6,'Flipped data - to use'!E$2:E$385) -> 0.19033495 | C6: =AVERAGEIF('Flipped data - to use'!$B$2:$B$417,'Scotland Data - use'!$A6,'Flipped data - to use'!F$2:F$385) -> 0.25967302 | D6: =AVERAGEIF('Flipped data - to use'!$B$2:$B$417,'Scotland Data - use'!$A6,'Flipped data - to use'!G$2:G$385) -> 0.25116567 | F6: =AVERAGEIF('Flipped data - to use'!$B$2:$B$417,'Scotland Data - use'!$A6,'Flipped data - to use'!I$2:I$385) -> 0.20720037 | G6: =AVERAGEIF('Flipped data - to use'!$B$2:$B$417,'Scotland Data - use'!$A6,'Flipped data - to use'!J$2:J$385) -> -0.049482573 | H6: =AVERAGEIF('Flipped data - to use'!$B$2:$B$417,'Scotland Data - use'!$A6,'Flipped data - to use'!K$2:K$385) -> 0.20074389
A7: 2015 | B7: =AVERAGEIF('Flipped data - to use'!$B$2:$B$417,'Scotland Data - use'!$A7,'Flipped data - to use'!E$2:E$385) -> 0.19186852 | C7: =AVERAGEIF('Flipped data - to use'!$B$2:$B$417,'Scotland Data - use'!$A7,'Flipped data - to use'!F$2:F$385) -> 0.26187231 | D7: =AVERAGEIF('Flipped data - to use'!$B$2:$B$417,'Scotland Data - use'!$A7,'Flipped data - to use'!G$2:G$385) -> 0.25085737 | F7: =AVERAGEIF('Flipped data - to use'!$B$2:$B$417,'Scotland Data - use'!$A7,'Flipped data - to use'!I$2:I$385) -> 0.19527796 | G7: =AVERAGEIF('Flipped data - to use'!$B$2:$B$417,'Scotland Data - use'!$A7,'Flipped data - to use'!J$2:J$385) -> -0.050642739 | H7: =AVERAGEIF('Flipped data - to use'!$B$2:$B$417,'Scotland Data - use'!$A7,'Flipped data - to use'!K$2:K$385) -> 0.22822441
A8: 2016 | B8: =AVERAGEIF('Flipped data - to use'!$B$2:$B$417,'Scotland Data - use'!$A8,'Flipped data - to use'!E$2:E$385) -> 0.19728792 | C8: =AVERAGEIF('Flipped data - to use'!$B$2:$B$417,'Scotland Data - use'!$A8,'Flipped data - to use'!F$2:F$385) -> 0.26709164 | D8: =AVERAGEIF('Flipped data - to use'!$B$2:$B$417,'Scotland Data - use'!$A8,'Flipped data - to use'!G$2:G$385) -> 0.24794309 | E8: =AVERAGEIF('Flipped data - to use'!$B$2:$B$417,'Scotland Data - use'!$A8,'Flipped data - to use'!H$2:H$385) -> 0.23053989 | F8: =AVERAGEIF('Flipped data - to use'!$B$2:$B$417,'Scotland Data - use'!$A8,'Flipped data - to use'!I$2:I$385) -> 0.20452939 | G8: =AVERAGEIF('Flipped data - to use'!$B$2:$B$417,'Scotland Data - use'!$A8,'Flipped data - to use'!J$2:J$385) -> -0.054701498 | H8: =AVERAGEIF('Flipped data - to use'!$B$2:$B$417,'Scotland Data - use'!$A8,'Flipped data - to use'!K$2:K$385) -> 0.24040142
A9: 2017 | B9: =AVERAGEIF('Flipped data - to use'!$B$2:$B$417,'Scotland Data - use'!$A9,'Flipped data - to use'!E$2:E$385) -> 0.1955486 | C9: =AVERAGEIF('Flipped data - to use'!$B$2:$B$417,'Scotland Data - use'!$A9,'Flipped data - to use'!F$2:F$385) -> 0.27151373 | D9: =AVERAGEIF('Flipped data - to use'!$B$2:$B$417,'Scotland Data - use'!$A9,'Flipped data - to use'!G$2:G$385) -> 0.25047409 | E9: =AVERAGEIF('Flipped data - to use'!$B$2:$B$417,'Scotland Data - use'!$A9,'Flipped data - to use'!H$2:H$385) -> 0.23053989 | F9: =AVERAGEIF('Flipped data - to use'!$B$2:$B$417,'Scotland Data - use'!$A9,'Flipped data - to use'!I$2:I$385) -> 0.20848717 | G9: =AVERAGEIF('Flipped data - to use'!$B$2:$B$417,'Scotland Data - use'!$A9,'Flipped data - to use'!J$2:J$385) -> -0.060511741 | H9: =AVERAGEIF('Flipped data - to use'!$B$2:$B$417,'Scotland Data - use'!$A9,'Flipped data - to use'!K$2:K$385) -> 0.25231914
A10: 2018 | B10: =AVERAGEIF('Flipped data - to use'!$B$2:$B$417,'Scotland Data - use'!$A10,'Flipped data - to use'!E$2:E$385) -> 0.20230876 | C10: =AVERAGEIF('Flipped data - to use'!$B$2:$B$417,'Scotland Data - use'!$A10,'Flipped data - to use'!F$2:F$385) -> 0.27726334 | D10: =AVERAGEIF('Flipped data - to use'!$B$2:$B$417,'Scotland Data - use'!$A10,'Flipped data - to use'!G$2:G$385) -> 0.25196297 | E10: =AVERAGEIF('Flipped data - to use'!$B$2:$B$417,'Scotland Data - use'!$A10,'Flipped data - to use'!H$2:H$385) -> 0.22591344 | F10: =AVERAGEIF('Flipped data - to use'!$B$2:$B$417,'Scotland Data - use'!$A10,'Flipped data - to use'!I$2:I$385) -> 0.20489251 | G10: =AVERAGEIF('Flipped data - to use'!$B$2:$B$417,'Scotland Data - use'!$A10,'Flipped data - to use'!J$2:J$385) -> -0.07251189 | H10: =AVERAGEIF('Flipped data - to use'!$B$2:$B$417,'Scotland Data - use'!$A10,'Flipped data - to use'!K$2:K$385) -> 0.2649191
A11: 2019 | B11: =AVERAGEIF('Flipped data - to use'!$B$2:$B$417,'Scotland Data - use'!$A11,'Flipped data - to use'!E$2:E$385) -> 0.2073147 | C11: =AVERAGEIF('Flipped data - to use'!$B$2:$B$417,'Scotland Data - use'!$A11,'Flipped data - to use'!F$2:F$385) -> 0.27799478 | D11: =AVERAGEIF('Flipped data - to use'!$B$2:$B$417,'Scotland Data - use'!$A11,'Flipped data - to use'!G$2:G$385) -> 0.2549618 | E11: =AVERAGEIF('Flipped data - to use'!$B$2:$B$417,'Scotland Data - use'!$A11,'Flipped data - to use'!H$2:H$385) -> 0.23148686 | F11: =AVERAGEIF('Flipped data - to use'!$B$2:$B$417,'Scotland Data - use'!$A11,'Flipped data - to use'!I$2:I$385) -> 0.21747131 | G11: =AVERAGEIF('Flipped data - to use'!$B$2:$B$417,'Scotland Data - use'!$A11,'Flipped data - to use'!J$2:J$385) -> -0.074804162 | H11: =AVERAGEIF('Flipped data - to use'!$B$2:$B$417,'Scotland Data - use'!$A11,'Flipped data - to use'!K$2:K$385) -> 0.26979287
A12: 2020 | B12: =AVERAGEIF('Flipped data - to use'!$B$2:$B$417,'Scotland Data - use'!$A12,'Flipped data - to use'!E$2:E$385) -> 0.22227151 | C12: =AVERAGEIF('Flipped data - to use'!$B$2:$B$417,'Scotland Data - use'!$A12,'Flipped data - to use'!F$2:F$385) -> 0.26803919 | D12: =AVERAGEIF('Flipped data - to use'!$B$2:$B$417,'Scotland Data - use'!$A12,'Flipped data - to use'!G$2:G$385) -> 0.25498675 | E12: =AVERAGEIF('Flipped data - to use'!$B$2:$B$417,'Scotland Data - use'!$A12,'Flipped data - to use'!H$2:H$385) -> 0.22950873 | F12: =AVERAGEIF('Flipped data - to use'!$B$2:$B$417,'Scotland Data - use'!$A12,'Flipped data - to use'!I$2:I$385) -> 0.20835619 | G12: =AVERAGEIF('Flipped data - to use'!$B$2:$B$417,'Scotland Data - use'!$A12,'Flipped data - to use'!J$2:J$385) -> -0.078110391 | H12: =AVERAGEIF('Flipped data - to use'!$B$2:$B$417,'Scotland Data - use'!$A12,'Flipped data - to use'!K$2:K$385) -> 0.27094396
A13: 2021 | B13: =AVERAGEIF('Flipped data - to use'!$B$2:$B$417,'Scotland Data - use'!$A13,'Flipped data - to use'!E$2:E$385) -> 0.21100585 | C13: =AVERAGEIF('Flipped data - to use'!$B$2:$B$417,'Scotland Data - use'!$A13,'Flipped data - to use'!F$2:F$385) -> 0.28315343 | D13: =AVERAGEIF('Flipped data - to use'!$B$2:$B$417,'Scotland Data - use'!$A13,'Flipped data - to use'!G$2:G$385) -> 0.25266845 | E13: =AVERAGEIF('Flipped data - to use'!$B$2:$B$417,'Scotland Data - use'!$A13,'Flipped data - to use'!H$2:H$385) -> 0.22681723 | F13: =AVERAGEIF('Flipped data - to use'!$B$2:$B$417,'Scotland Data - use'!$A13,'Flipped data - to use'!I$2:I$385) -> 0.21612732 | G13: =AVERAGEIF('Flipped data - to use'!$B$2:$B$417,'Scotland Data - use'!$A13,'Flipped data - to use'!J$2:J$385) -> -0.078971263 | H13: =AVERAGEIF('Flipped data - to use'!$B$2:$B$417,'Scotland Data - use'!$A13,'Flipped data - to use'!K$2:K$385) -> 0.27335775
A14: 2022 | B14: =AVERAGEIF('Flipped data - to use'!$B$2:$B$417,'Scotland Data - use'!$A14,'Flipped data - to use'!E$2:E$385) -> 0.21176916 | C14: =AVERAGEIF('Flipped data - to use'!$B$2:$B$417,'Scotland Data - use'!$A14,'Flipped data - to use'!F$2:F$385) -> 0.27676312 | D14: =AVERAGEIF('Flipped data - to use'!$B$2:$B$417,'Scotland Data - use'!$A14,'Flipped data - to use'!G$2:G$385) -> 0.25338739 | E14: =AVERAGEIF('Flipped data - to use'!$B$2:$B$417,'Scotland Data - use'!$A14,'Flipped data - to use'!H$2:H$385) -> 0.22203352 | F14: =AVERAGEIF('Flipped data - to use'!$B$2:$B$417,'Scotland Data - use'!$A14,'Flipped data - to use'!I$2:I$385) -> 0.2122709 | G14: =AVERAGEIF('Flipped data - to use'!$B$2:$B$417,'Scotland Data - use'!$A14,'Flipped data - to use'!J$2:J$385) -> -0.081122192 | H14: =AVERAGEIF('Flipped data - to use'!$B$2:$B$417,'Scotland Data - use'!$A14,'Flipped data - to use'!K$2:K$385) -> 0.27119247
