Workbook

Sheet Intro
B4: All data in IGZs, and 2011 DZs
B6: Scotland is average of LAs
B8: Imputed data has been removed in this version
B10: Some indicators are flipped as the model assumes that high is good, and for a number of indicators that isn't the case
B11: Crime
B12: Child Poverty
B13: Emergency Admissions
B14: Early Mortality
B16: Help sheet that explains methodology here: | G16: https://impservihub.sharepoint.com/:w:/r/sites/tpi-benchmarking/Shared%20Documents/CPP%20Benchmarking/DATA%20LIBRARY/2018%20Data%20Library/Inequality%20tool%20data/Duncan_Index_Feb_19/DI%20help%20sheet_feb_19.docx?d=w34893cdbb8f241e6b72080985edc35d4&csf=1&e=CUd1Hn
B20: At Scotland level looks like for positive destinations inequality is reducing, whereas for Emgerency admissions it is increasing. It is worth remembering that we have added imputed data here, and for positive destinations there are 4 or 5 years of imputed data at the end.

Sheet Duncan index by FINALSep25
B1: year | C1: la | D1: total.pop | E1: crime | F1: CP | G1: Attain | H1: PD | I1: EA | J1: Depop | K1: EM
A2: 1 | B2: 2011 | C2: Aberdeen City | D2: 222460 | E2: -0.31674135 | F2: -0.35332173 | G2: 0.35959972 | H2: 0.25166122 | I2: -0.28360098 | J2: 0.099535812 | K2: -0.28908209
A3: 2 | B3: 2011 | C3: Aberdeenshire | D3: 253650 | E3: -0.24584142 | F3: -0.30987757 | G3: 0.26760463 | H3: 0.15178088 | I3: -0.20235262 | J3: -0.11372867 | K3: -0.28922431
A4: 3 | B4: 2011 | C4: Angus | D4: 116200 | E4: -0.29585229 | F4: -0.28838779 | G4: 0.28778355 | H4: 0.16641681 | I4: -0.13283411 | J4: 0.024102286 | K4: -0.26000054
A5: 4 | B5: 2011 | C5: Argyll and Bute | D5: 88930 | E5: -0.18303493 | F5: -0.12029587 | G5: 0.20275143 | H5: 0.091160495 | I5: -0.14743962 | J5: 0.0045176033 | K5: -0.24037439
A6: 5 | B6: 2011 | C6: Clackmannanshire | D6: 51500 | E6: -0.20883626 | F6: -0.18155364 | G6: 0.16876915 | H6: 0.23117964 | I6: -0.071985312 | J6: -0.045799874 | K6: -0.17159796
A7: 6 | B7: 2011 | C7: Dumfries and Galloway | D7: 151410 | E7: -0.18101792 | F7: -0.15780861 | G7: 0.17177404 | H7: 0.1466735 | I7: -0.10705973 | J7: 0.0062126527 | K7: -0.18030842
A8: 7 | B8: 2011 | C8: Dundee City | D8: 147200 | E8: -0.26971112 | F8: -0.25776033 | G8: 0.31830435 | H8: 0.25826158 | I8: -0.26015307 | J8: -0.080515889 | K8: -0.24431544
A9: 8 | B9: 2011 | C9: East Ayrshire | D9: 122690 | E9: -0.17569551 | F9: -0.26116342 | G9: 0.26395642 | H9: 0.22276415 | I9: -0.24895291 | J9: 0.013386198 | K9: -0.25456195
A10: 9 | B10: 2011 | C10: East Dunbartonshire | D10: 105000 | E10: -0.057720787 | F10: -0.33871897 | G10: 0.33544744 | H10: 0.26749272 | I10: -0.28865725 | J10: 0.032710354 | K10: -0.3450018
A11: 10 | B11: 2011 | C11: East Lothian | D11: 99920 | E11: -0.18349085 | F11: -0.17851631 | G11: 0.19805223 | H11: 0.1898162 | I11: -0.14389348 | J11: 0.06562692 | K11: -0.15512403
A12: 11 | B12: 2011 | C12: East Renfrewshire | D12: 90810 | E12: -0.29719492 | F12: -0.38136667 | G12: 0.40531313 | H12: 0.33732314 | I12: -0.26416739 | J12: 0.10383436 | K12: -0.37885914
A13: 12 | B13: 2011 | C13: Edinburgh, City of | D13: 477940 | E13: -0.33514628 | F13: -0.37689169 | G13: 0.41263103 | H13: 0.32359458 | I13: -0.34348118 | J13: 0.021215813 | K13: -0.37880339
... A417: 416 | B417: 2023 | C417: West Lothian | D417: 181310 | E417: -0.22567223 | F417: -0.29159818 | G417: 0.27317217 | H417: 0.18818946 | I417: -0.2356302 | J417: -0.053612873 | K417: -0.27405313

Sheet Flipped data - to use
B1: year | C1: la | D1: total.pop | E1: crime | F1: CP | G1: Attain | H1: PD | I1: EA | J1: Depop | K1: EM
A2: 1 | B2: 2011 | C2: Aberdeen City | D2: 222460 | E2: ='Duncan index by FINALSep25'!E2*-1 -> 0.31674135 | I2: ='Duncan index by FINALSep25'!I2*-1 -> 0.28360098 | J2: ='Duncan index by FINALSep25'!J2 -> 0.099535812 | K2: ='Duncan index by FINALSep25'!K2*-1 -> 0.28908209
A3: 2 | B3: 2011 | C3: Aberdeenshire | D3: 253650 | E3: ='Duncan index by FINALSep25'!E3*-1 -> 0.24584142 | I3: ='Duncan index by FINALSep25'!I3*-1 -> 0.20235262 | J3: ='Duncan index by FINALSep25'!J3 -> -0.11372867 | K3: ='Duncan index by FINALSep25'!K3*-1 -> 0.28922431
A4: 3 | B4: 2011 | C4: Angus | D4: 116200 | E4: ='Duncan index by FINALSep25'!E4*-1 -> 0.29585229 | I4: ='Duncan index by FINALSep25'!I4*-1 -> 0.13283411 | J4: ='Duncan index by FINALSep25'!J4 -> 0.024102286 | K4: ='Duncan index by FINALSep25'!K4*-1 -> 0.26000054
A5: 4 | B5: 2011 | C5: Argyll and Bute | D5: 88930 | E5: ='Duncan index by FINALSep25'!E5*-1 -> 0.18303493 | I5: ='Duncan index by FINALSep25'!I5*-1 -> 0.14743962 | J5: ='Duncan index by FINALSep25'!J5 -> 0.0045176033 | K5: ='Duncan index by FINALSep25'!K5*-1 -> 0.24037439
A6: 5 | B6: 2011 | C6: Clackmannanshire | D6: 51500 | E6: ='Duncan index by FINALSep25'!E6*-1 -> 0.20883626 | I6: ='Duncan index by FINALSep25'!I6*-1 -> 0.071985312 | J6: ='Duncan index by FINALSep25'!J6 -> -0.045799874 | K6: ='Duncan index by FINALSep25'!K6*-1 -> 0.17159796
A7: 6 | B7: 2011 | C7: Dumfries and Galloway | D7: 151410 | E7: ='Duncan index by FINALSep25'!E7*-1 -> 0.18101792 | I7: ='Duncan index by FINALSep25'!I7*-1 -> 0.10705973 | J7: ='Duncan index by FINALSep25'!J7 -> 0.0062126527 | K7: ='Duncan index by FINALSep25'!K7*-1 -> 0.18030842
A8: 7 | B8: 2011 | C8: Dundee City | D8: 147200 | E8: ='Duncan index by FINALSep25'!E8*-1 -> 0.26971112 | I8: ='Duncan index by FINALSep25'!I8*-1 -> 0.26015307 | J8: ='Duncan index by FINALSep25'!J8 -> -0.080515889 | K8: ='Duncan index by FINALSep25'!K8*-1 -> 0.24431544
A9: 8 | B9: 2011 | C9: East Ayrshire | D9: 122690 | E9: ='Duncan index by FINALSep25'!E9*-1 -> 0.17569551 | I9: ='Duncan index by FINALSep25'!I9*-1 -> 0.24895291 | J9: ='Duncan index by FINALSep25'!J9 -> 0.013386198 | K9: ='Duncan index by FINALSep25'!K9*-1 -> 0.25456195
A10: 9 | B10: 2011 | C10: East Dunbartonshire | D10: 105000 | E10: ='Duncan index by FINALSep25'!E10*-1 -> 0.057720787 | I10: ='Duncan index by FINALSep25'!I10*-1 -> 0.28865725 | J10: ='Duncan index by FINALSep25'!J10 -> 0.032710354 | K10: ='Duncan index by FINALSep25'!K10*-1 -> 0.3450018
A11: 10 | B11: 2011 | C11: East Lothian | D11: 99920 | E11: ='Duncan index by FINALSep25'!E11*-1 -> 0.18349085 | I11: ='Duncan index by FINALSep25'!I11*-1 -> 0.14389348 | J11: ='Duncan index by FINALSep25'!J11 -> 0.06562692 | K11: ='Duncan index by FINALSep25'!K11*-1 -> 0.15512403
A12: 11 | B12: 2011 | C12: East Renfrewshire | D12: 90810 | E12: ='Duncan index by FINALSep25'!E12*-1 -> 0.29719492 | I12: ='Duncan index by FINALSep25'!I12*-1 -> 0.26416739 | J12: ='Duncan index by FINALSep25'!J12 -> 0.10383436 | K12: ='Duncan index by FINALSep25'!K12*-1 -> 0.37885914
A13: 12 | B13: 2011 | C13: Edinburgh, City of | D13: 477940 | E13: ='Duncan index by FINALSep25'!E13*-1 -> 0.33514628 | I13: ='Duncan index by FINALSep25'!I13*-1 -> 0.34348118 | J13: ='Duncan index by FINALSep25'!J13 -> 0.021215813 | K13: ='Duncan index by FINALSep25'!K13*-1 -> 0.37880339
... A65: 64 | B65: 2012 | C65: West Lothian | D65: 176010 | E65: ='Duncan index by FINALSep25'!E65*-1 -> 0.19168559 | I65: ='Duncan index by FINALSep25'!I65*-1 -> 0.14606981 | J65: ='Duncan index by FINALSep25'!J65 -> 0.066160765 | K65: ='Duncan index by FINALSep25'!K65*-1 -> 0.20605908
A66: 65 | B66: 2013 | C66: Aberdeen City | D66: 227070 | E66: ='Duncan index by FINALSep25'!E66*-1 -> 0.26332753 | G66: ='Duncan index by FINALSep25'!G66 -> 0.3534847 | I66: ='Duncan index by FINALSep25'!I66*-1 -> 0.33436911 | J66: ='Duncan index by FINALSep25'!J66 -> 0.0075414866 | K66: ='Duncan index by FINALSep25'!K66*-1 -> 0.28273703
A67: 66 | B67: 2013 | C67: Aberdeenshire | D67: 257770 | E67: ='Duncan index by FINALSep25'!E67*-1 -> 0.24094812 | G67: ='Duncan index by FINALSep25'!G67 -> 0.2840029 | I67: ='Duncan index by FINALSep25'!I67*-1 -> 0.20207808 | J67: ='Duncan index by FINALSep25'!J67 -> -0.17304072 | K67: ='Duncan index by FINALSep25'!K67*-1 -> 0.28375163
A68: 67 | B68: 2013 | C68: Angus | D68: 116290 | E68: ='Duncan index by FINALSep25'!E68*-1 -> 0.25963043 | G68: ='Duncan index by FINALSep25'!G68 -> 0.28245497 | I68: ='Duncan index by FINALSep25'!I68*-1 -> 0.15984978 | J68: ='Duncan index by FINALSep25'!J68 -> 0.010107884 | K68: ='Duncan index by FINALSep25'!K68*-1 -> 0.27221243
A69: 68 | B69: 2013 | C69: Argyll and Bute | D69: 88050 | E69: ='Duncan index by FINALSep25'!E69*-1 -> 0.17620388 | G69: ='Duncan index by FINALSep25'!G69 -> 0.17618174 | I69: ='Duncan index by FINALSep25'!I69*-1 -> 0.19133395 | J69: ='Duncan index by FINALSep25'!J69 -> -0.091358155 | K69: ='Duncan index by FINALSep25'!K69*-1 -> 0.19508588
A70: 69 | B70: 2013 | C70: Clackmannanshire | D70: 51280 | E70: ='Duncan index by FINALSep25'!E70*-1 -> 0.20076096 | G70: ='Duncan index by FINALSep25'!G70 -> 0.23311495 | I70: ='Duncan index by FINALSep25'!I70*-1 -> 0.13608257 | J70: ='Duncan index by FINALSep25'!J70 -> -0.059801176 | K70: ='Duncan index by FINALSep25'!K70*-1 -> 0.22489928
A71: 70 | B71: 2013 | C71: Dumfries and Galloway | D71: 150280 | E71: ='Duncan index by FINALSep25'!E71*-1 -> 0.19439329 | G71: ='Duncan index by FINALSep25'!G71 -> 0.20056016 | I71: ='Duncan index by FINALSep25'!I71*-1 -> 0.15167066 | J71: ='Duncan index by FINALSep25'!J71 -> -0.0041000474 | K71: ='Duncan index by FINALSep25'!K71*-1 -> 0.1994405
A72: 71 | B72: 2013 | C72: Dundee City | D72: 148100 | E72: ='Duncan index by FINALSep25'!E72*-1 -> 0.2796959 | G72: ='Duncan index by FINALSep25'!G72 -> 0.3269266 | I72: ='Duncan index by FINALSep25'!I72*-1 -> 0.1926335 | J72: ='Duncan index by FINALSep25'!J72 -> -0.10964243 | K72: ='Duncan index by FINALSep25'!K72*-1 -> 0.23261577
A73: 72 | B73: 2013 | C73: East Ayrshire | D73: 122430 | E73: ='Duncan index by FINALSep25'!E73*-1 -> 0.06066012 | G73: ='Duncan index by FINALSep25'!G73 -> 0.25696239 | I73: ='Duncan index by FINALSep25'!I73*-1 -> 0.23026058 | J73: ='Duncan index by FINALSep25'!J73 -> -0.046886481 | K73: ='Duncan index by FINALSep25'!K73*-1 -> 0.24507593
A74: 73 | B74: 2013 | C74: East Dunbartonshire | D74: 105840 | E74: ='Duncan index by FINALSep25'!E74*-1 -> 0.03963528 | G74: ='Duncan index by FINALSep25'!G74 -> 0.33439568 | I74: ='Duncan index by FINALSep25'!I74*-1 -> 0.33409605 | J74: ='Duncan index by FINALSep25'!J74 -> 0.048749503 | K74: ='Duncan index by FINALSep25'!K74*-1 -> 0.35137562
A75: 74 | B75: 2013 | C75: East Lothian | D75: 101390 | E75: ='Duncan index by FINALSep25'!E75*-1 -> 0.18115427 | G75: ='Duncan index by FINALSep25'!G75 -> 0.23135926 | I75: ='Duncan index by FINALSep25'!I75*-1 -> 0.19587723 | J75: ='Duncan index by FINALSep25'!J75 -> 0.090630176 | K75: ='Duncan index by FINALSep25'!K75*-1 -> 0.21300806
A76: 75 | B76: 2013 | C76: East Renfrewshire | D76: 91530 | E76: ='Duncan index by FINALSep25'!E76*-1 -> 0.19247419 | G76: ='Duncan index by FINALSep25'!G76 -> 0.39835885 | I76: ='Duncan index by FINALSep25'!I76*-1 -> 0.34548108 | J76: ='Duncan index by FINALSep25'!J76 -> 0.079412143 | K76: ='Duncan index by FINALSep25'!K76*-1 -> 0.38510967
A77: 76 | B77: 2013 | C77: Edinburgh, City of | D77: 487460 | E77: ='Duncan index by FINALSep25'!E77*-1 -> 0.35094061 | G77: ='Duncan index by FINALSep25'!G77 -> 0.44670474 | I77: ='Duncan index by FINALSep25'!I77*-1 -> 0.38474482 | J77: ='Duncan index by FINALSep25'!J77 -> -0.0010532951 | K77: ='Duncan index by FINALSep25'!K77*-1 -> 0.42060911
... A97: 96 | B97: 2013 | C97: West Lothian | D97: 176160 | E97: ='Duncan index by FINALSep25'!E97*-1 -> 0.20858694 | G97: ='Duncan index by FINALSep25'!G97 -> 0.25819063 | I97: ='Duncan index by FINALSep25'!I97*-1 -> 0.17767502 | J97: ='Duncan index by FINALSep25'!J97 -> 0.083302962 | K97: ='Duncan index by FINALSep25'!K97*-1 -> 0.22085662
A98: 97 | B98: 2014 | C98: Aberdeen City | D98: 228920 | E98: ='Duncan index by FINALSep25'!E98*-1 -> 0.24934958 | F98: ='Duncan index by FINALSep25'!F98*-1 -> 0.35750369 | G98: ='Duncan index by FINALSep25'!G98 -> 0.32822436 | I98: ='Duncan index by FINALSep25'!I98*-1 -> 0.31677917 | J98: ='Duncan index by FINALSep25'!J98 -> -0.018829033 | K98: ='Duncan index by FINALSep25'!K98*-1 -> 0.25270882
A99: 98 | B99: 2014 | C99: Aberdeenshire | D99: 260530 | E99: ='Duncan index by FINALSep25'!E99*-1 -> 0.23275962 | F99: ='Duncan index by FINALSep25'!F99*-1 -> 0.32884778 | G99: ='Duncan index by FINALSep25'!G99 -> 0.28689901 | I99: ='Duncan index by FINALSep25'!I99*-1 -> 0.19068897 | J99: ='Duncan index by FINALSep25'!J99 -> -0.17734436 | K99: ='Duncan index by FINALSep25'!K99*-1 -> 0.20046255
A100: 99 | B100: 2014 | C100: Angus | D100: 116740 | E100: ='Duncan index by FINALSep25'!E100*-1 -> 0.25015697 | F100: ='Duncan index by FINALSep25'!F100*-1 -> 0.26647897 | G100: ='Duncan index by FINALSep25'!G100 -> 0.27123768 | I100: ='Duncan index by FINALSep25'!I100*-1 -> 0.20806787 | J100: ='Duncan index by FINALSep25'!J100 -> 0.01028743 | K100: ='Duncan index by FINALSep25'!K100*-1 -> 0.2243834
A101: 100 | B101: 2014 | C101: Argyll and Bute | D101: 87650 | E101: ='Duncan index by FINALSep25'!E101*-1 -> 0.17018137 | F101: ='Duncan index by FINALSep25'!F101*-1 -> 0.15924345 | G101: ='Duncan index by FINALSep25'!G101 -> 0.19671069 | I101: ='Duncan index by FINALSep25'!I101*-1 -> 0.20060494 | J101: ='Duncan index by FINALSep25'!J101 -> -0.12186526 | K101: ='Duncan index by FINALSep25'!K101*-1 -> 0.17565657
A102: 101 | B102: 2014 | C102: Clackmannanshire | D102: 51190 | E102: ='Duncan index by FINALSep25'!E102*-1 -> 0.19762504 | F102: ='Duncan index by FINALSep25'!F102*-1 -> 0.22639616 | G102: ='Duncan index by FINALSep25'!G102 -> 0.2397749 | I102: ='Duncan index by FINALSep25'!I102*-1 -> 0.16264346 | J102: ='Duncan index by FINALSep25'!J102 -> -0.055013546 | K102: ='Duncan index by FINALSep25'!K102*-1 -> 0.18659783
A103: 102 | B103: 2014 | C103: Dumfries and Galloway | D103: 149960 | E103: ='Duncan index by FINALSep25'!E103*-1 -> 0.17797318 | F103: ='Duncan index by FINALSep25'!F103*-1 -> 0.2040867 | G103: ='Duncan index by FINALSep25'!G103 -> 0.20290355 | I103: ='Duncan index by FINALSep25'!I103*-1 -> 0.17885351 | J103: ='Duncan index by FINALSep25'!J103 -> -0.022656234 | K103: ='Duncan index by FINALSep25'!K103*-1 -> 0.13951809
A104: 103 | B104: 2014 | C104: Dundee City | D104: 148130 | E104: ='Duncan index by FINALSep25'!E104*-1 -> 0.28602755 | F104: ='Duncan index by FINALSep25'!F104*-1 -> 0.28719344 | G104: ='Duncan index by FINALSep25'!G104 -> 0.3242801 | I104: ='Duncan index by FINALSep25'!I104*-1 -> 0.21268379 | J104: ='Duncan index by FINALSep25'!J104 -> -0.10456201 | K104: ='Duncan index by FINALSep25'!K104*-1 -> 0.25201564
A105: 104 | B105: 2014 | C105: East Ayrshire | D105: 122130 | E105: ='Duncan index by FINALSep25'!E105*-1 -> 0.12444992 | F105: ='Duncan index by FINALSep25'!F105*-1 -> 0.26862521 | G105: ='Duncan index by FINALSep25'!G105 -> 0.24945557 | I105: ='Duncan index by FINALSep25'!I105*-1 -> 0.22062428 | J105: ='Duncan index by FINALSep25'!J105 -> -0.065805164 | K105: ='Duncan index by FINALSep25'!K105*-1 -> 0.18258336
A106: 105 | B106: 2014 | C106: East Dunbartonshire | D106: 106710 | E106: ='Duncan index by FINALSep25'!E106*-1 -> 0.089800937 | F106: ='Duncan index by FINALSep25'!F106*-1 -> 0.32807714 | G106: ='Duncan index by FINALSep25'!G106 -> 0.32459175 | I106: ='Duncan index by FINALSep25'!I106*-1 -> 0.31729074 | J106: ='Duncan index by FINALSep25'!J106 -> 0.050658131 | K106: ='Duncan index by FINALSep25'!K106*-1 -> 0.25392849
A107: 106 | B107: 2014 | C107: East Lothian | D107: 102090 | E107: ='Duncan index by FINALSep25'!E107*-1 -> 0.18352709 | F107: ='Duncan index by FINALSep25'!F107*-1 -> 0.22787462 | G107: ='Duncan index by FINALSep25'!G107 -> 0.24179132 | I107: ='Duncan index by FINALSep25'!I107*-1 -> 0.21605177 | J107: ='Duncan index by FINALSep25'!J107 -> 0.071592703 | K107: ='Duncan index by FINALSep25'!K107*-1 -> 0.16682275
A108: 107 | B108: 2014 | C108: East Renfrewshire | D108: 92410 | E108: ='Duncan index by FINALSep25'!E108*-1 -> 0.21585913 | F108: ='Duncan index by FINALSep25'!F108*-1 -> 0.39121322 | G108: ='Duncan index by FINALSep25'!G108 -> 0.41079268 | I108: ='Duncan index by FINALSep25'!I108*-1 -> 0.36708324 | J108: ='Duncan index by FINALSep25'!J108 -> 0.070403282 | K108: ='Duncan index by FINALSep25'!K108*-1 -> 0.35685298
A109: 108 | B109: 2014 | C109: Edinburgh, City of | D109: 492610 | E109: ='Duncan index by FINALSep25'!E109*-1 -> 0.33842401 | F109: ='Duncan index by FINALSep25'!F109*-1 -> 0.4165102 | G109: ='Duncan index by FINALSep25'!G109 -> 0.44874447 | I109: ='Duncan index by FINALSep25'!I109*-1 -> 0.40138285 | J109: ='Duncan index by FINALSep25'!J109 -> 0.0077161535 | K109: ='Duncan index by FINALSep25'!K109*-1 -> 0.40317356
... A161: 160 | B161: 2015 | C161: West Lothian | D161: 178550 | E161: ='Duncan index by FINALSep25'!E161*-1 -> 0.20962886 | F161: ='Duncan index by FINALSep25'!F161*-1 -> 0.25467051 | G161: ='Duncan index by FINALSep25'!G161 -> 0.24174822 | I161: ='Duncan index by FINALSep25'!I161*-1 -> 0.20852515 | J161: ='Duncan index by FINALSep25'!J161 -> 0.0508667 | K161: ='Duncan index by FINALSep25'!K161*-1 -> 0.20017354
...

Sheet Scotland Data - use
B1: crime | C1: CP | D1: Attain | E1: PD | F1: EA | G1: Depop | H1: EM
A2: 2011 | B2: =AVERAGEIF('Flipped data - to use'!$B$1:$B$416,'Scotland Data - use'!$A2,'Flipped data - to use'!E$1:E$416) -> 0.1989217 | F2: =AVERAGEIF('Flipped data - to use'!$B$1:$B$416,'Scotland Data - use'!$A2,'Flipped data - to use'!I$1:I$416) -> 0.17961283 | G2: =AVERAGEIF('Flipped data - to use'!$B$1:$B$416,'Scotland Data - use'!$A2,'Flipped data - to use'!J$1:J$416) -> -0.016199621 | H2: =AVERAGEIF('Flipped data - to use'!$B$1:$B$416,'Scotland Data - use'!$A2,'Flipped data - to use'!K$1:K$416) -> 0.23697505
A3: 2012 | B3: =AVERAGEIF('Flipped data - to use'!$B$1:$B$416,'Scotland Data - use'!$A3,'Flipped data - to use'!E$1:E$416) -> 0.18864381 | F3: =AVERAGEIF('Flipped data - to use'!$B$1:$B$416,'Scotland Data - use'!$A3,'Flipped data - to use'!I$1:I$416) -> 0.19169946 | G3: =AVERAGEIF('Flipped data - to use'!$B$1:$B$416,'Scotland Data - use'!$A3,'Flipped data - to use'!J$1:J$416) -> -0.029468231 | H3: =AVERAGEIF('Flipped data - to use'!$B$1:$B$416,'Scotland Data - use'!$A3,'Flipped data - to use'!K$1:K$416) -> 0.23901115
A4: 2013 | B4: =AVERAGEIF('Flipped data - to use'!$B$1:$B$416,'Scotland Data - use'!$A4,'Flipped data - to use'!E$1:E$416) -> 0.18165657 | D4: =AVERAGEIF('Flipped data - to use'!$B$1:$B$416,'Scotland Data - use'!$A4,'Flipped data - to use'!G$1:G$416) -> 0.25685522 | F4: =AVERAGEIF('Flipped data - to use'!$B$1:$B$416,'Scotland Data - use'!$A4,'Flipped data - to use'!I$1:I$416) -> 0.20897692 | G4: =AVERAGEIF('Flipped data - to use'!$B$1:$B$416,'Scotland Data - use'!$A4,'Flipped data - to use'!J$1:J$416) -> -0.04334525 | H4: =AVERAGEIF('Flipped data - to use'!$B$1:$B$416,'Scotland Data - use'!$A4,'Flipped data - to use'!K$1:K$416) -> 0.24551927
A5: 2014 | B5: =AVERAGEIF('Flipped data - to use'!$B$1:$B$416,'Scotland Data - use'!$A5,'Flipped data - to use'!E$1:E$416) -> 0.19033495 | C5: =AVERAGEIF('Flipped data - to use'!$B$1:$B$416,'Scotland Data - use'!$A5,'Flipped data - to use'!F$1:F$416) -> 0.25967302 | D5: =AVERAGEIF('Flipped data - to use'!$B$1:$B$416,'Scotland Data - use'!$A5,'Flipped data - to use'!G$1:G$416) -> 0.25116567 | F5: =AVERAGEIF('Flipped data - to use'!$B$1:$B$416,'Scotland Data - use'!$A5,'Flipped data - to use'!I$1:I$416) -> 0.20720037 | G5: =AVERAGEIF('Flipped data - to use'!$B$1:$B$416,'Scotland Data - use'!$A5,'Flipped data - to use'!J$1:J$416) -> -0.049482573 | H5: =AVERAGEIF('Flipped data - to use'!$B$1:$B$416,'Scotland Data - use'!$A5,'Flipped data - to use'!K$1:K$416) -> 0.20074389
A6: 2015 | B6: =AVERAGEIF('Flipped data - to use'!$B$1:$B$416,'Scotland Data - use'!$A6,'Flipped data - to use'!E$1:E$416) -> 0.19186852 | C6: =AVERAGEIF('Flipped data - to use'!$B$1:$B$416,'Scotland Data - use'!$A6,'Flipped data - to use'!F$1:F$416) -> 0.26187231 | D6: =AVERAGEIF('Flipped data - to use'!$B$1:$B$416,'Scotland Data - use'!$A6,'Flipped data - to use'!G$1:G$416) -> 0.25085737 | F6: =AVERAGEIF('Flipped data - to use'!$B$1:$B$416,'Scotland Data - use'!$A6,'Flipped data - to use'!I$1:I$416) -> 0.19527796 | G6: =AVERAGEIF('Flipped data - to use'!$B$1:$B$416,'Scotland Data - use'!$A6,'Flipped data - to use'!J$1:J$416) -> -0.050642739 | H6: =AVERAGEIF('Flipped data - to use'!$B$1:$B$416,'Scotland Data - use'!$A6,'Flipped data - to use'!K$1:K$416) -> 0.22822441
A7: 2016 | B7: =AVERAGEIF('Flipped data - to use'!$B$1:$B$416,'Scotland Data - use'!$A7,'Flipped data - to use'!E$1:E$416) -> 0.19728792 | C7: =AVERAGEIF('Flipped data - to use'!$B$1:$B$416,'Scotland Data - use'!$A7,'Flipped data - to use'!F$1:F$416) -> 0.26709164 | D7: =AVERAGEIF('Flipped data - to use'!$B$1:$B$416,'Scotland Data - use'!$A7,'Flipped data - to use'!G$1:G$416) -> 0.24794309 | E7: =AVERAGEIF('Flipped data - to use'!$B$1:$B$416,'Scotland Data - use'!$A7,'Flipped data - to use'!H$1:H$416) -> 0.23053989 | F7: =AVERAGEIF('Flipped data - to use'!$B$1:$B$416,'Scotland Data - use'!$A7,'Flipped data - to use'!I$1:I$416) -> 0.20452939 | G7: =AVERAGEIF('Flipped data - to use'!$B$1:$B$416,'Scotland Data - use'!$A7,'Flipped data - to use'!J$1:J$416) -> -0.054701498 | H7: =AVERAGEIF('Flipped data - to use'!$B$1:$B$416,'Scotland Data - use'!$A7,'Flipped data - to use'!K$1:K$416) -> 0.24040142
A8: 2017 | B8: =AVERAGEIF('Flipped data - to use'!$B$1:$B$416,'Scotland Data - use'!$A8,'Flipped data - to use'!E$1:E$416) -> 0.1955486 | C8: =AVERAGEIF('Flipped data - to use'!$B$1:$B$416,'Scotland Data - use'!$A8,'Flipped data - to use'!F$1:F$416) -> 0.27151373 | D8: =AVERAGEIF('Flipped data - to use'!$B$1:$B$416,'Scotland Data - use'!$A8,'Flipped data - to use'!G$1:G$416) -> 0.25047409 | E8: =AVERAGEIF('Flipped data - to use'!$B$1:$B$416,'Scotland Data - use'!$A8,'Flipped data - to use'!H$1:H$416) -> 0.23053989 | F8: =AVERAGEIF('Flipped data - to use'!$B$1:$B$416,'Scotland Data - use'!$A8,'Flipped data - to use'!I$1:I$416) -> 0.20848717 | G8: =AVERAGEIF('Flipped data - to use'!$B$1:$B$416,'Scotland Data - use'!$A8,'Flipped data - to use'!J$1:J$416) -> -0.060511741 | H8: =AVERAGEIF('Flipped data - to use'!$B$1:$B$416,'Scotland Data - use'!$A8,'Flipped data - to use'!K$1:K$416) -> 0.25231914
A9: 2018 | B9: =AVERAGEIF('Flipped data - to use'!$B$1:$B$416,'Scotland Data - use'!$A9,'Flipped data - to use'!E$1:E$416) -> 0.20157433 | C9: =AVERAGEIF('Flipped data - to use'!$B$1:$B$416,'Scotland Data - use'!$A9,'Flipped data - to use'!F$1:F$416) -> 0.27646865 | D9: =AVERAGEIF('Flipped data - to use'!$B$1:$B$416,'Scotland Data - use'!$A9,'Flipped data - to use'!G$1:G$416) -> 0.25196297 | E9: =AVERAGEIF('Flipped data - to use'!$B$1:$B$416,'Scotland Data - use'!$A9,'Flipped data - to use'!H$1:H$416) -> 0.22591344 | F9: =AVERAGEIF('Flipped data - to use'!$B$1:$B$416,'Scotland Data - use'!$A9,'Flipped data - to use'!I$1:I$416) -> 0.20489251 | G9: =AVERAGEIF('Flipped data - to use'!$B$1:$B$416,'Scotland Data - use'!$A9,'Flipped data - to use'!J$1:J$416) -> -0.058687712 | H9: =AVERAGEIF('Flipped data - to use'!$B$1:$B$416,'Scotland Data - use'!$A9,'Flipped data - to use'!K$1:K$416) -> 0.26449355
A10: 2019 | B10: =AVERAGEIF('Flipped data - to use'!$B$1:$B$416,'Scotland Data - use'!$A10,'Flipped data - to use'!E$1:E$416) -> 0.20581886 | C10: =AVERAGEIF('Flipped data - to use'!$B$1:$B$416,'Scotland Data - use'!$A10,'Flipped data - to use'!F$1:F$416) -> 0.28005514 | D10: =AVERAGEIF('Flipped data - to use'!$B$1:$B$416,'Scotland Data - use'!$A10,'Flipped data - to use'!G$1:G$416) -> 0.2549618 | E10: =AVERAGEIF('Flipped data - to use'!$B$1:$B$416,'Scotland Data - use'!$A10,'Flipped data - to use'!H$1:H$416) -> 0.23148686 | F10: =AVERAGEIF('Flipped data - to use'!$B$1:$B$416,'Scotland Data - use'!$A10,'Flipped data - to use'!I$1:I$416) -> 0.21747131 | G10: =AVERAGEIF('Flipped data - to use'!$B$1:$B$416,'Scotland Data - use'!$A10,'Flipped data - to use'!J$1:J$416) -> -0.061406807 | H10: =AVERAGEIF('Flipped data - to use'!$B$1:$B$416,'Scotland Data - use'!$A10,'Flipped data - to use'!K$1:K$416) -> 0.26947307
A11: 2020 | B11: =AVERAGEIF('Flipped data - to use'!$B$1:$B$416,'Scotland Data - use'!$A11,'Flipped data - to use'!E$1:E$416) -> 0.22087744 | C11: =AVERAGEIF('Flipped data - to use'!$B$1:$B$416,'Scotland Data - use'!$A11,'Flipped data - to use'!F$1:F$416) -> 0.27022137 | D11: =AVERAGEIF('Flipped data - to use'!$B$1:$B$416,'Scotland Data - use'!$A11,'Flipped data - to use'!G$1:G$416) -> 0.25498675 | E11: =AVERAGEIF('Flipped data - to use'!$B$1:$B$416,'Scotland Data - use'!$A11,'Flipped data - to use'!H$1:H$416) -> 0.22950873 | F11: =AVERAGEIF('Flipped data - to use'!$B$1:$B$416,'Scotland Data - use'!$A11,'Flipped data - to use'!I$1:I$416) -> 0.20835619 | G11: =AVERAGEIF('Flipped data - to use'!$B$1:$B$416,'Scotland Data - use'!$A11,'Flipped data - to use'!J$1:J$416) -> -0.05947906 | H11: =AVERAGEIF('Flipped data - to use'!$B$1:$B$416,'Scotland Data - use'!$A11,'Flipped data - to use'!K$1:K$416) -> 0.27120848
A12: 2021 | B12: =AVERAGEIF('Flipped data - to use'!$B$1:$B$416,'Scotland Data - use'!$A12,'Flipped data - to use'!E$1:E$416) -> 0.2088235 | C12: =AVERAGEIF('Flipped data - to use'!$B$1:$B$416,'Scotland Data - use'!$A12,'Flipped data - to use'!F$1:F$416) -> 0.27189916 | D12: =AVERAGEIF('Flipped data - to use'!$B$1:$B$416,'Scotland Data - use'!$A12,'Flipped data - to use'!G$1:G$416) -> 0.25266845 | E12: =AVERAGEIF('Flipped data - to use'!$B$1:$B$416,'Scotland Data - use'!$A12,'Flipped data - to use'!H$1:H$416) -> 0.22681723 | F12: =AVERAGEIF('Flipped data - to use'!$B$1:$B$416,'Scotland Data - use'!$A12,'Flipped data - to use'!I$1:I$416) -> 0.21800313 | G12: =AVERAGEIF('Flipped data - to use'!$B$1:$B$416,'Scotland Data - use'!$A12,'Flipped data - to use'!J$1:J$416) -> -0.055720266 | H12: =AVERAGEIF('Flipped data - to use'!$B$1:$B$416,'Scotland Data - use'!$A12,'Flipped data - to use'!K$1:K$416) -> 0.27195111
A13: 2022 | B13: =AVERAGEIF('Flipped data - to use'!$B$1:$B$416,'Scotland Data - use'!$A13,'Flipped data - to use'!E$1:E$416) -> 0.20968557 | C13: =AVERAGEIF('Flipped data - to use'!$B$1:$B$416,'Scotland Data - use'!$A13,'Flipped data - to use'!F$1:F$416) -> 0.27005271 | D13: =AVERAGEIF('Flipped data - to use'!$B$1:$B$416,'Scotland Data - use'!$A13,'Flipped data - to use'!G$1:G$416) -> 0.25338739 | E13: =AVERAGEIF('Flipped data - to use'!$B$1:$B$416,'Scotland Data - use'!$A13,'Flipped data - to use'!H$1:H$416) -> 0.22203352 | F13: =AVERAGEIF('Flipped data - to use'!$B$1:$B$416,'Scotland Data - use'!$A13,'Flipped data - to use'!I$1:I$416) -> 0.21862763 | G13: =AVERAGEIF('Flipped data - to use'!$B$1:$B$416,'Scotland Data - use'!$A13,'Flipped data - to use'!J$1:J$416) -> -0.055720266 | H13: =AVERAGEIF('Flipped data - to use'!$B$1:$B$416,'Scotland Data - use'!$A13,'Flipped data - to use'!K$1:K$416) -> 0.27177779
A14: 2023 | B14: =AVERAGEIF('Flipped data - to use'!$B$1:$B$416,'Scotland Data - use'!$A14,'Flipped data - to use'!E$1:E$416) -> 0.19857018 | C14: =AVERAGEIF('Flipped data - to use'!$B$1:$B$416,'Scotland Data - use'!$A14,'Flipped data - to use'!F$1:F$416) -> 0.26655924 | D14: =AVERAGEIF('Flipped data - to use'!$B$1:$B$416,'Scotland Data - use'!$A14,'Flipped data - to use'!G$1:G$416) -> 0.25434533 | E14: =AVERAGEIF('Flipped data - to use'!$B$1:$B$416,'Scotland Data - use'!$A14,'Flipped data - to use'!H$1:H$416) -> 0.22636312 | F14: =AVERAGEIF('Flipped data - to use'!$B$1:$B$416,'Scotland Data - use'!$A14,'Flipped data - to use'!I$1:I$416) -> 0.20900192 | G14: =AVERAGEIF('Flipped data - to use'!$B$1:$B$416,'Scotland Data - use'!$A14,'Flipped data - to use'!J$1:J$416) -> -0.056192917 | H14: =AVERAGEIF('Flipped data - to use'!$B$1:$B$416,'Scotland Data - use'!$A14,'Flipped data - to use'!K$1:K$416) -> 0.26674069
